2021-06-04 07:39:42,725 - telegram.ext.updater - ERROR - Error while getting Updates: urllib3 HTTPError HTTPSConnectionPool(host='api.telegram.org', port=443): Max retries exceeded with url: /bot1780780782:AAGSGKBe12aNd9Yh82VpkEQvD1vrMMf1IvM/getUpdates (Caused by NewConnectionError('<telegram.vendor.ptb_urllib3.urllib3.connection.VerifiedHTTPSConnection object at 0x7f987da97d00>: Failed to establish a new connection: [Errno -3] Temporary failure in name resolution'))
2021-06-04 07:39:42,725 - __main__ - WARNING - Update "None" caused error "urllib3 HTTPError HTTPSConnectionPool(host='api.telegram.org', port=443): Max retries exceeded with url: /bot1780780782:AAGSGKBe12aNd9Yh82VpkEQvD1vrMMf1IvM/getUpdates (Caused by NewConnectionError('<telegram.vendor.ptb_urllib3.urllib3.connection.VerifiedHTTPSConnection object at 0x7f987da97d00>: Failed to establish a new connection: [Errno -3] Temporary failure in name resolution'))"
2021-06-04 07:40:12,757 - telegram.vendor.ptb_urllib3.urllib3.connectionpool - WARNING - Retrying (Retry(total=2, connect=None, read=None, redirect=None)) after connection broken by 'NewConnectionError('<telegram.vendor.ptb_urllib3.urllib3.connection.VerifiedHTTPSConnection object at 0x7f987c018eb0>: Failed to establish a new connection: [Errno -3] Temporary failure in name resolution')': /bot1780780782:AAGSGKBe12aNd9Yh82VpkEQvD1vrMMf1IvM/getUpdates
2021-06-04 07:40:12,759 - telegram.vendor.ptb_urllib3.urllib3.connectionpool - WARNING - Retrying (Retry(total=1, connect=None, read=None, redirect=None)) after connection broken by 'NewConnectionError('<telegram.vendor.ptb_urllib3.urllib3.connection.VerifiedHTTPSConnection object at 0x7f987da97a90>: Failed to establish a new connection: [Errno -3] Temporary failure in name resolution')': /bot1780780782:AAGSGKBe12aNd9Yh82VpkEQvD1vrMMf1IvM/getUpdates
2021-06-04 07:40:12,761 - telegram.vendor.ptb_urllib3.urllib3.connectionpool - WARNING - Retrying (Retry(total=0, connect=None, read=None, redirect=None)) after connection broken by 'NewConnectionError('<telegram.vendor.ptb_urllib3.urllib3.connection.VerifiedHTTPSConnection object at 0x7f987da97850>: Failed to establish a new connection: [Errno -3] Temporary failure in name resolution')': /bot1780780782:AAGSGKBe12aNd9Yh82VpkEQvD1vrMMf1IvM/getUpdates
2021-06-04 07:40:12,763 - telegram.ext.updater - ERROR - Error while getting Updates: urllib3 HTTPError HTTPSConnectionPool(host='api.telegram.org', port=443): Max retries exceeded with url: /bot1780780782:AAGSGKBe12aNd9Yh82VpkEQvD1vrMMf1IvM/getUpdates (Caused by NewConnectionError('<telegram.vendor.ptb_urllib3.urllib3.connection.VerifiedHTTPSConnection object at 0x7f987da36f40>: Failed to establish a new connection: [Errno -3] Temporary failure in name resolution'))
2021-06-04 07:40:12,764 - __main__ - WARNING - Update "None" caused error "urllib3 HTTPError HTTPSConnectionPool(host='api.telegram.org', port=443): Max retries exceeded with url: /bot1780780782:AAGSGKBe12aNd9Yh82VpkEQvD1vrMMf1IvM/getUpdates (Caused by NewConnectionError('<telegram.vendor.ptb_urllib3.urllib3.connection.VerifiedHTTPSConnection object at 0x7f987da36f40>: Failed to establish a new connection: [Errno -3] Temporary failure in name resolution'))"
2021-06-04 07:40:42,791 - telegram.vendor.ptb_urllib3.urllib3.connectionpool - WARNING - Retrying (Retry(total=2, connect=None, read=None, redirect=None)) after connection broken by 'NewConnectionError('<telegram.vendor.ptb_urllib3.urllib3.connection.VerifiedHTTPSConnection object at 0x7f987c018280>: Failed to establish a new connection: [Errno -3] Temporary failure in name resolution')': /bot1780780782:AAGSGKBe12aNd9Yh82VpkEQvD1vrMMf1IvM/getUpdates
2021-06-04 07:40:42,794 - telegram.vendor.ptb_urllib3.urllib3.connectionpool - WARNING - Retrying (Retry(total=1, connect=None, read=None, redirect=None)) after connection broken by 'NewConnectionError('<telegram.vendor.ptb_urllib3.urllib3.connection.VerifiedHTTPSConnection object at 0x7f987c028700>: Failed to establish a new connection: [Errno -3] Temporary failure in name resolution')': /bot1780780782:AAGSGKBe12aNd9Yh82VpkEQvD1vrMMf1IvM/getUpdates
2021-06-04 07:40:42,796 - telegram.vendor.ptb_urllib3.urllib3.connectionpool - WARNING - Retrying (Retry(total=0, connect=None, read=None, redirect=None)) after connection broken by 'NewConnectionError('<telegram.vendor.ptb_urllib3.urllib3.connection.VerifiedHTTPSConnection object at 0x7f987da97f40>: Failed to establish a new connection: [Errno -3] Temporary failure in name resolution')': /bot1780780782:AAGSGKBe12aNd9Yh82VpkEQvD1vrMMf1IvM/getUpdates
2021-06-04 07:40:42,798 - telegram.ext.updater - ERROR - Error while getting Updates: urllib3 HTTPError HTTPSConnectionPool(host='api.telegram.org', port=443): Max retries exceeded with url: /bot1780780782:AAGSGKBe12aNd9Yh82VpkEQvD1vrMMf1IvM/getUpdates (Caused by NewConnectionError('<telegram.vendor.ptb_urllib3.urllib3.connection.VerifiedHTTPSConnection object at 0x7f987c018880>: Failed to establish a new connection: [Errno -3] Temporary failure in name resolution'))
2021-06-04 07:40:42,799 - __main__ - WARNING - Update "None" caused error "urllib3 HTTPError HTTPSConnectionPool(host='api.telegram.org', port=443): Max retries exceeded with url: /bot1780780782:AAGSGKBe12aNd9Yh82VpkEQvD1vrMMf1IvM/getUpdates (Caused by NewConnectionError('<telegram.vendor.ptb_urllib3.urllib3.connection.VerifiedHTTPSConnection object at 0x7f987c018880>: Failed to establish a new connection: [Errno -3] Temporary failure in name resolution'))"
2021-06-04 07:41:12,827 - telegram.vendor.ptb_urllib3.urllib3.connectionpool - WARNING - Retrying (Retry(total=2, connect=None, read=None, redirect=None)) after connection broken by 'NewConnectionError('<telegram.vendor.ptb_urllib3.urllib3.connection.VerifiedHTTPSConnection object at 0x7f987c018610>: Failed to establish a new connection: [Errno -3] Temporary failure in name resolution')': /bot1780780782:AAGSGKBe12aNd9Yh82VpkEQvD1vrMMf1IvM/getUpdates
2021-06-04 07:41:12,828 - telegram.vendor.ptb_urllib3.urllib3.connectionpool - WARNING - Retrying (Retry(total=1, connect=None, read=None, redirect=None)) after connection broken by 'NewConnectionError('<telegram.vendor.ptb_urllib3.urllib3.connection.VerifiedHTTPSConnection object at 0x7f987c018a30>: Failed to establish a new connection: [Errno -3] Temporary failure in name resolution')': /bot1780780782:AAGSGKBe12aNd9Yh82VpkEQvD1vrMMf1IvM/getUpdates
2021-06-04 07:41:12,828 - telegram.vendor.ptb_urllib3.urllib3.connectionpool - WARNING - Retrying (Retry(total=0, connect=None, read=None, redirect=None)) after connection broken by 'NewConnectionError('<telegram.vendor.ptb_urllib3.urllib3.connection.VerifiedHTTPSConnection object at 0x7f987c0185e0>: Failed to establish a new connection: [Errno -3] Temporary failure in name resolution')': /bot1780780782:AAGSGKBe12aNd9Yh82VpkEQvD1vrMMf1IvM/getUpdates
2021-06-04 07:41:12,829 - telegram.ext.updater - ERROR - Error while getting Updates: urllib3 HTTPError HTTPSConnectionPool(host='api.telegram.org', port=443): Max retries exceeded with url: /bot1780780782:AAGSGKBe12aNd9Yh82VpkEQvD1vrMMf1IvM/getUpdates (Caused by NewConnectionError('<telegram.vendor.ptb_urllib3.urllib3.connection.VerifiedHTTPSConnection object at 0x7f987dba9130>: Failed to establish a new connection: [Errno -3] Temporary failure in name resolution'))
2021-06-04 07:41:12,829 - __main__ - WARNING - Update "None" caused error "urllib3 HTTPError HTTPSConnectionPool(host='api.telegram.org', port=443): Max retries exceeded with url: /bot1780780782:AAGSGKBe12aNd9Yh82VpkEQvD1vrMMf1IvM/getUpdates (Caused by NewConnectionError('<telegram.vendor.ptb_urllib3.urllib3.connection.VerifiedHTTPSConnection object at 0x7f987dba9130>: Failed to establish a new connection: [Errno -3] Temporary failure in name resolution'))"
2021-06-04 07:41:42,861 - telegram.vendor.ptb_urllib3.urllib3.connectionpool - WARNING - Retrying (Retry(total=2, connect=None, read=None, redirect=None)) after connection broken by 'NewConnectionError('<telegram.vendor.ptb_urllib3.urllib3.connection.VerifiedHTTPSConnection object at 0x7f987c018430>: Failed to establish a new connection: [Errno -3] Temporary failure in name resolution')': /bot1780780782:AAGSGKBe12aNd9Yh82VpkEQvD1vrMMf1IvM/getUpdates
2021-06-04 07:41:42,864 - telegram.vendor.ptb_urllib3.urllib3.connectionpool - WARNING - Retrying (Retry(total=1, connect=None, read=None, redirect=None)) after connection broken by 'NewConnectionError('<telegram.vendor.ptb_urllib3.urllib3.connection.VerifiedHTTPSConnection object at 0x7f9874fed6a0>: Failed to establish a new connection: [Errno -3] Temporary failure in name resolution')': /bot1780780782:AAGSGKBe12aNd9Yh82VpkEQvD1vrMMf1IvM/getUpdates
2021-06-04 07:41:42,866 - telegram.vendor.ptb_urllib3.urllib3.connectionpool - WARNING - Retrying (Retry(total=0, connect=None, read=None, redirect=None)) after connection broken by 'NewConnectionError('<telegram.vendor.ptb_urllib3.urllib3.connection.VerifiedHTTPSConnection object at 0x7f9874fed370>: Failed to establish a new connection: [Errno -3] Temporary failure in name resolution')': /bot1780780782:AAGSGKBe12aNd9Yh82VpkEQvD1vrMMf1IvM/getUpdates
2021-06-04 07:41:42,868 - telegram.ext.updater - ERROR - Error while getting Updates: urllib3 HTTPError HTTPSConnectionPool(host='api.telegram.org', port=443): Max retries exceeded with url: /bot1780780782:AAGSGKBe12aNd9Yh82VpkEQvD1vrMMf1IvM/getUpdates (Caused by NewConnectionError('<telegram.vendor.ptb_urllib3.urllib3.connection.VerifiedHTTPSConnection object at 0x7f9874fed250>: Failed to establish a new connection: [Errno -3] Temporary failure in name resolution'))
2021-06-04 07:41:42,869 - __main__ - WARNING - Update "None" caused error "urllib3 HTTPError HTTPSConnectionPool(host='api.telegram.org', port=443): Max retries exceeded with url: /bot1780780782:AAGSGKBe12aNd9Yh82VpkEQvD1vrMMf1IvM/getUpdates (Caused by NewConnectionError('<telegram.vendor.ptb_urllib3.urllib3.connection.VerifiedHTTPSConnection object at 0x7f9874fed250>: Failed to establish a new connection: [Errno -3] Temporary failure in name resolution'))"
2021-06-04 07:42:12,880 - telegram.vendor.ptb_urllib3.urllib3.connectionpool - WARNING - Retrying (Retry(total=2, connect=None, read=None, redirect=None)) after connection broken by 'NewConnectionError('<telegram.vendor.ptb_urllib3.urllib3.connection.VerifiedHTTPSConnection object at 0x7f987c018be0>: Failed to establish a new connection: [Errno -3] Temporary failure in name resolution')': /bot1780780782:AAGSGKBe12aNd9Yh82VpkEQvD1vrMMf1IvM/getUpdates
2021-06-04 07:42:12,881 - telegram.vendor.ptb_urllib3.urllib3.connectionpool - WARNING - Retrying (Retry(total=1, connect=None, read=None, redirect=None)) after connection broken by 'NewConnectionError('<telegram.vendor.ptb_urllib3.urllib3.connection.VerifiedHTTPSConnection object at 0x7f9874fed160>: Failed to establish a new connection: [Errno -3] Temporary failure in name resolution')': /bot1780780782:AAGSGKBe12aNd9Yh82VpkEQvD1vrMMf1IvM/getUpdates
2021-06-04 07:42:12,881 - telegram.vendor.ptb_urllib3.urllib3.connectionpool - WARNING - Retrying (Retry(total=0, connect=None, read=None, redirect=None)) after connection broken by 'NewConnectionError('<telegram.vendor.ptb_urllib3.urllib3.connection.VerifiedHTTPSConnection object at 0x7f9874fed790>: Failed to establish a new connection: [Errno -3] Temporary failure in name resolution')': /bot1780780782:AAGSGKBe12aNd9Yh82VpkEQvD1vrMMf1IvM/getUpdates
2021-06-04 07:42:12,882 - telegram.ext.updater - ERROR - Error while getting Updates: urllib3 HTTPError HTTPSConnectionPool(host='api.telegram.org', port=443): Max retries exceeded with url: /bot1780780782:AAGSGKBe12aNd9Yh82VpkEQvD1vrMMf1IvM/getUpdates (Caused by NewConnectionError('<telegram.vendor.ptb_urllib3.urllib3.connection.VerifiedHTTPSConnection object at 0x7f987c007ee0>: Failed to establish a new connection: [Errno -3] Temporary failure in name resolution'))
2021-06-04 07:42:12,883 - __main__ - WARNING - Update "None" caused error "urllib3 HTTPError HTTPSConnectionPool(host='api.telegram.org', port=443): Max retries exceeded with url: /bot1780780782:AAGSGKBe12aNd9Yh82VpkEQvD1vrMMf1IvM/getUpdates (Caused by NewConnectionError('<telegram.vendor.ptb_urllib3.urllib3.connection.VerifiedHTTPSConnection object at 0x7f987c007ee0>: Failed to establish a new connection: [Errno -3] Temporary failure in name resolution'))"
2021-06-04 07:42:42,916 - telegram.vendor.ptb_urllib3.urllib3.connectionpool - WARNING - Retrying (Retry(total=2, connect=None, read=None, redirect=None)) after connection broken by 'NewConnectionError('<telegram.vendor.ptb_urllib3.urllib3.connection.VerifiedHTTPSConnection object at 0x7f987da97c40>: Failed to establish a new connection: [Errno -3] Temporary failure in name resolution')': /bot1780780782:AAGSGKBe12aNd9Yh82VpkEQvD1vrMMf1IvM/getUpdates
2021-06-04 07:42:42,918 - telegram.vendor.ptb_urllib3.urllib3.connectionpool - WARNING - Retrying (Retry(total=1, connect=None, read=None, redirect=None)) after connection broken by 'NewConnectionError('<telegram.vendor.ptb_urllib3.urllib3.connection.VerifiedHTTPSConnection object at 0x7f987c007c40>: Failed to establish a new connection: [Errno -3] Temporary failure in name resolution')': /bot1780780782:AAGSGKBe12aNd9Yh82VpkEQvD1vrMMf1IvM/getUpdates
2021-06-04 07:42:42,920 - telegram.vendor.ptb_urllib3.urllib3.connectionpool - WARNING - Retrying (Retry(total=0, connect=None, read=None, redirect=None)) after connection broken by 'NewConnectionError('<telegram.vendor.ptb_urllib3.urllib3.connection.VerifiedHTTPSConnection object at 0x7f987c007910>: Failed to establish a new connection: [Errno -3] Temporary failure in name resolution')': /bot1780780782:AAGSGKBe12aNd9Yh82VpkEQvD1vrMMf1IvM/getUpdates
2021-06-04 07:42:42,923 - telegram.ext.updater - ERROR - Error while getting Updates: urllib3 HTTPError HTTPSConnectionPool(host='api.telegram.org', port=443): Max retries exceeded with url: /bot1780780782:AAGSGKBe12aNd9Yh82VpkEQvD1vrMMf1IvM/getUpdates (Caused by NewConnectionError('<telegram.vendor.ptb_urllib3.urllib3.connection.VerifiedHTTPSConnection object at 0x7f987cee8520>: Failed to establish a new connection: [Errno -3] Temporary failure in name resolution'))
2021-06-04 07:42:42,923 - __main__ - WARNING - Update "None" caused error "urllib3 HTTPError HTTPSConnectionPool(host='api.telegram.org', port=443): Max retries exceeded with url: /bot1780780782:AAGSGKBe12aNd9Yh82VpkEQvD1vrMMf1IvM/getUpdates (Caused by NewConnectionError('<telegram.vendor.ptb_urllib3.urllib3.connection.VerifiedHTTPSConnection object at 0x7f987cee8520>: Failed to establish a new connection: [Errno -3] Temporary failure in name resolution'))"
2021-06-04 07:43:12,947 - telegram.vendor.ptb_urllib3.urllib3.connectionpool - WARNING - Retrying (Retry(total=2, connect=None, read=None, redirect=None)) after connection broken by 'NewConnectionError('<telegram.vendor.ptb_urllib3.urllib3.connection.VerifiedHTTPSConnection object at 0x7f987dba91f0>: Failed to establish a new connection: [Errno -3] Temporary failure in name resolution')': /bot1780780782:AAGSGKBe12aNd9Yh82VpkEQvD1vrMMf1IvM/getUpdates
2021-06-04 07:43:12,949 - telegram.vendor.ptb_urllib3.urllib3.connectionpool - WARNING - Retrying (Retry(total=1, connect=None, read=None, redirect=None)) after connection broken by 'NewConnectionError('<telegram.vendor.ptb_urllib3.urllib3.connection.VerifiedHTTPSConnection object at 0x7f987daab0d0>: Failed to establish a new connection: [Errno -3] Temporary failure in name resolution')': /bot1780780782:AAGSGKBe12aNd9Yh82VpkEQvD1vrMMf1IvM/getUpdates
2021-06-04 07:43:12,951 - telegram.vendor.ptb_urllib3.urllib3.connectionpool - WARNING - Retrying (Retry(total=0, connect=None, read=None, redirect=None)) after connection broken by 'NewConnectionError('<telegram.vendor.ptb_urllib3.urllib3.connection.VerifiedHTTPSConnection object at 0x7f987c028550>: Failed to establish a new connection: [Errno -3] Temporary failure in name resolution')': /bot1780780782:AAGSGKBe12aNd9Yh82VpkEQvD1vrMMf1IvM/getUpdates
2021-06-04 07:43:12,952 - telegram.ext.updater - ERROR - Error while getting Updates: urllib3 HTTPError HTTPSConnectionPool(host='api.telegram.org', port=443): Max retries exceeded with url: /bot1780780782:AAGSGKBe12aNd9Yh82VpkEQvD1vrMMf1IvM/getUpdates (Caused by NewConnectionError('<telegram.vendor.ptb_urllib3.urllib3.connection.VerifiedHTTPSConnection object at 0x7f987c028310>: Failed to establish a new connection: [Errno -3] Temporary failure in name resolution'))
2021-06-04 07:43:12,953 - __main__ - WARNING - Update "None" caused error "urllib3 HTTPError HTTPSConnectionPool(host='api.telegram.org', port=443): Max retries exceeded with url: /bot1780780782:AAGSGKBe12aNd9Yh82VpkEQvD1vrMMf1IvM/getUpdates (Caused by NewConnectionError('<telegram.vendor.ptb_urllib3.urllib3.connection.VerifiedHTTPSConnection object at 0x7f987c028310>: Failed to establish a new connection: [Errno -3] Temporary failure in name resolution'))"
2021-06-04 07:43:42,979 - telegram.vendor.ptb_urllib3.urllib3.connectionpool - WARNING - Retrying (Retry(total=2, connect=None, read=None, redirect=None)) after connection broken by 'NewConnectionError('<telegram.vendor.ptb_urllib3.urllib3.connection.VerifiedHTTPSConnection object at 0x7f9874fed490>: Failed to establish a new connection: [Errno -3] Temporary failure in name resolution')': /bot1780780782:AAGSGKBe12aNd9Yh82VpkEQvD1vrMMf1IvM/getUpdates
2021-06-04 07:43:42,981 - telegram.vendor.ptb_urllib3.urllib3.connectionpool - WARNING - Retrying (Retry(total=1, connect=None, read=None, redirect=None)) after connection broken by 'NewConnectionError('<telegram.vendor.ptb_urllib3.urllib3.connection.VerifiedHTTPSConnection object at 0x7f987c028df0>: Failed to establish a new connection: [Errno -3] Temporary failure in name resolution')': /bot1780780782:AAGSGKBe12aNd9Yh82VpkEQvD1vrMMf1IvM/getUpdates
2021-06-04 07:43:42,982 - telegram.vendor.ptb_urllib3.urllib3.connectionpool - WARNING - Retrying (Retry(total=0, connect=None, read=None, redirect=None)) after connection broken by 'NewConnectionError('<telegram.vendor.ptb_urllib3.urllib3.connection.VerifiedHTTPSConnection object at 0x7f987c028f40>: Failed to establish a new connection: [Errno -3] Temporary failure in name resolution')': /bot1780780782:AAGSGKBe12aNd9Yh82VpkEQvD1vrMMf1IvM/getUpdates
2021-06-04 07:43:42,982 - telegram.ext.updater - ERROR - Error while getting Updates: urllib3 HTTPError HTTPSConnectionPool(host='api.telegram.org', port=443): Max retries exceeded with url: /bot1780780782:AAGSGKBe12aNd9Yh82VpkEQvD1vrMMf1IvM/getUpdates (Caused by NewConnectionError('<telegram.vendor.ptb_urllib3.urllib3.connection.VerifiedHTTPSConnection object at 0x7f987c028a90>: Failed to establish a new connection: [Errno -3] Temporary failure in name resolution'))
2021-06-04 07:43:42,982 - __main__ - WARNING - Update "None" caused error "urllib3 HTTPError HTTPSConnectionPool(host='api.telegram.org', port=443): Max retries exceeded with url: /bot1780780782:AAGSGKBe12aNd9Yh82VpkEQvD1vrMMf1IvM/getUpdates (Caused by NewConnectionError('<telegram.vendor.ptb_urllib3.urllib3.connection.VerifiedHTTPSConnection object at 0x7f987c028a90>: Failed to establish a new connection: [Errno -3] Temporary failure in name resolution'))"
2021-06-04 07:44:13,015 - telegram.vendor.ptb_urllib3.urllib3.connectionpool - WARNING - Retrying (Retry(total=2, connect=None, read=None, redirect=None)) after connection broken by 'NewConnectionError('<telegram.vendor.ptb_urllib3.urllib3.connection.VerifiedHTTPSConnection object at 0x7f987c028ca0>: Failed to establish a new connection: [Errno -3] Temporary failure in name resolution')': /bot1780780782:AAGSGKBe12aNd9Yh82VpkEQvD1vrMMf1IvM/getUpdates
2021-06-04 07:44:13,019 - telegram.vendor.ptb_urllib3.urllib3.connectionpool - WARNING - Retrying (Retry(total=1, connect=None, read=None, redirect=None)) after connection broken by 'NewConnectionError('<telegram.vendor.ptb_urllib3.urllib3.connection.VerifiedHTTPSConnection object at 0x7f987c0285b0>: Failed to establish a new connection: [Errno -3] Temporary failure in name resolution')': /bot1780780782:AAGSGKBe12aNd9Yh82VpkEQvD1vrMMf1IvM/getUpdates
2021-06-04 07:44:13,021 - telegram.vendor.ptb_urllib3.urllib3.connectionpool - WARNING - Retrying (Retry(total=0, connect=None, read=None, redirect=None)) after connection broken by 'NewConnectionError('<telegram.vendor.ptb_urllib3.urllib3.connection.VerifiedHTTPSConnection object at 0x7f987c028610>: Failed to establish a new connection: [Errno -3] Temporary failure in name resolution')': /bot1780780782:AAGSGKBe12aNd9Yh82VpkEQvD1vrMMf1IvM/getUpdates
2021-06-04 07:44:13,023 - telegram.ext.updater - ERROR - Error while getting Updates: urllib3 HTTPError HTTPSConnectionPool(host='api.telegram.org', port=443): Max retries exceeded with url: /bot1780780782:AAGSGKBe12aNd9Yh82VpkEQvD1vrMMf1IvM/getUpdates (Caused by NewConnectionError('<telegram.vendor.ptb_urllib3.urllib3.connection.VerifiedHTTPSConnection object at 0x7f987daab0d0>: Failed to establish a new connection: [Errno -3] Temporary failure in name resolution'))
2021-06-04 07:44:13,024 - __main__ - WARNING - Update "None" caused error "urllib3 HTTPError HTTPSConnectionPool(host='api.telegram.org', port=443): Max retries exceeded with url: /bot1780780782:AAGSGKBe12aNd9Yh82VpkEQvD1vrMMf1IvM/getUpdates (Caused by NewConnectionError('<telegram.vendor.ptb_urllib3.urllib3.connection.VerifiedHTTPSConnection object at 0x7f987daab0d0>: Failed to establish a new connection: [Errno -3] Temporary failure in name resolution'))"
